[2023-12-16T13:13:19.551+0500] {taskinstance.py:1159} INFO - Dependencies all met for dep_context=non-requeueable deps ti=<TaskInstance: etl_json_dag.transform manual__2023-12-16T08:13:11.674016+00:00 [queued]>
[2023-12-16T13:13:19.558+0500] {taskinstance.py:1159} INFO - Dependencies all met for dep_context=requeueable deps ti=<TaskInstance: etl_json_dag.transform manual__2023-12-16T08:13:11.674016+00:00 [queued]>
[2023-12-16T13:13:19.559+0500] {taskinstance.py:1361} INFO - Starting attempt 1 of 2
[2023-12-16T13:13:19.577+0500] {taskinstance.py:1382} INFO - Executing <Task(PythonOperator): transform> on 2023-12-16 08:13:11.674016+00:00
[2023-12-16T13:13:19.579+0500] {standard_task_runner.py:57} INFO - Started process 9589 to run task
[2023-12-16T13:13:19.581+0500] {standard_task_runner.py:84} INFO - Running: ['airflow', 'tasks', 'run', 'etl_json_dag', 'transform', 'manual__2023-12-16T08:13:11.674016+00:00', '--job-id', '19', '--raw', '--subdir', 'DAGS_FOLDER/etl_dag.py', '--cfg-path', '/tmp/tmpf7nmnqlf']
[2023-12-16T13:13:19.582+0500] {standard_task_runner.py:85} INFO - Job 19: Subtask transform
[2023-12-16T13:13:19.618+0500] {task_command.py:416} INFO - Running <TaskInstance: etl_json_dag.transform manual__2023-12-16T08:13:11.674016+00:00 [running]> on host DESKTOP-32G5QSE.
[2023-12-16T13:13:19.686+0500] {taskinstance.py:1662} INFO - Exporting env vars: AIRFLOW_CTX_DAG_OWNER='airflow' AIRFLOW_CTX_DAG_ID='etl_json_dag' AIRFLOW_CTX_TASK_ID='transform' AIRFLOW_CTX_EXECUTION_DATE='2023-12-16T08:13:11.674016+00:00' AIRFLOW_CTX_TRY_NUMBER='1' AIRFLOW_CTX_DAG_RUN_ID='manual__2023-12-16T08:13:11.674016+00:00'
[2023-12-16T13:13:19.687+0500] {etl_dag.py:20} INFO - Data received in transform_data: {'size': 1, 'parse_time_nanoseconds': 47091, 'object_or_array': 'object', 'validate': True, 'empty': False}
[2023-12-16T13:13:19.687+0500] {taskinstance.py:1937} ERROR - Task failed with exception
Traceback (most recent call last):
  File "/home/sourav/.local/lib/python3.10/site-packages/airflow/operators/python.py", line 192, in execute
    return_value = self.execute_callable()
  File "/home/sourav/.local/lib/python3.10/site-packages/airflow/operators/python.py", line 209, in execute_callable
    return self.python_callable(*self.op_args, **self.op_kwargs)
  File "/home/sourav/airflow/dags/etl_dag.py", line 22, in transform_data
    data['new_field'] = 'example_value'
TypeError: 'str' object does not support item assignment
[2023-12-16T13:13:19.691+0500] {taskinstance.py:1400} INFO - Marking task as UP_FOR_RETRY. dag_id=etl_json_dag, task_id=transform, execution_date=20231216T081311, start_date=20231216T081319, end_date=20231216T081319
[2023-12-16T13:13:19.708+0500] {standard_task_runner.py:104} ERROR - Failed to execute job 19 for task transform ('str' object does not support item assignment; 9589)
[2023-12-16T13:13:19.714+0500] {local_task_job_runner.py:228} INFO - Task exited with return code 1
[2023-12-16T13:13:19.731+0500] {taskinstance.py:2778} INFO - 0 downstream tasks scheduled from follow-on schedule check
