[2023-12-16T14:20:31.449+0500] {taskinstance.py:1159} INFO - Dependencies all met for dep_context=non-requeueable deps ti=<TaskInstance: etl_json_dag.git_push manual__2023-12-16T09:15:09.134981+00:00 [queued]>
[2023-12-16T14:20:31.455+0500] {taskinstance.py:1159} INFO - Dependencies all met for dep_context=requeueable deps ti=<TaskInstance: etl_json_dag.git_push manual__2023-12-16T09:15:09.134981+00:00 [queued]>
[2023-12-16T14:20:31.455+0500] {taskinstance.py:1361} INFO - Starting attempt 2 of 2
[2023-12-16T14:20:31.477+0500] {taskinstance.py:1382} INFO - Executing <Task(BashOperator): git_push> on 2023-12-16 09:15:09.134981+00:00
[2023-12-16T14:20:31.479+0500] {standard_task_runner.py:57} INFO - Started process 25450 to run task
[2023-12-16T14:20:31.483+0500] {standard_task_runner.py:84} INFO - Running: ['airflow', 'tasks', 'run', 'etl_json_dag', 'git_push', 'manual__2023-12-16T09:15:09.134981+00:00', '--job-id', '50', '--raw', '--subdir', 'DAGS_FOLDER/etl_dag.py', '--cfg-path', '/tmp/tmp58x4wf3c']
[2023-12-16T14:20:31.483+0500] {standard_task_runner.py:85} INFO - Job 50: Subtask git_push
[2023-12-16T14:20:31.523+0500] {task_command.py:416} INFO - Running <TaskInstance: etl_json_dag.git_push manual__2023-12-16T09:15:09.134981+00:00 [running]> on host DESKTOP-32G5QSE.
[2023-12-16T14:20:31.583+0500] {taskinstance.py:1662} INFO - Exporting env vars: AIRFLOW_CTX_DAG_OWNER='airflow' AIRFLOW_CTX_DAG_ID='etl_json_dag' AIRFLOW_CTX_TASK_ID='git_push' AIRFLOW_CTX_EXECUTION_DATE='2023-12-16T09:15:09.134981+00:00' AIRFLOW_CTX_TRY_NUMBER='2' AIRFLOW_CTX_DAG_RUN_ID='manual__2023-12-16T09:15:09.134981+00:00'
[2023-12-16T14:20:31.589+0500] {subprocess.py:63} INFO - Tmp dir root location: /tmp
[2023-12-16T14:20:31.590+0500] {subprocess.py:75} INFO - Running command: ['/usr/bin/bash', '-c', 'cd /home/sourav/airflow && git push origin new']
[2023-12-16T14:20:31.594+0500] {subprocess.py:86} INFO - Output:
[2023-12-16T14:20:32.208+0500] {subprocess.py:93} INFO - fatal: could not read Username for 'https://github.com': No such device or address
[2023-12-16T14:20:32.209+0500] {subprocess.py:97} INFO - Command exited with return code 128
[2023-12-16T14:20:32.216+0500] {taskinstance.py:1937} ERROR - Task failed with exception
Traceback (most recent call last):
  File "/home/sourav/.local/lib/python3.10/site-packages/airflow/operators/bash.py", line 210, in execute
    raise AirflowException(
airflow.exceptions.AirflowException: Bash command failed. The command returned a non-zero exit code 128.
[2023-12-16T14:20:32.218+0500] {taskinstance.py:1400} INFO - Marking task as FAILED. dag_id=etl_json_dag, task_id=git_push, execution_date=20231216T091509, start_date=20231216T092031, end_date=20231216T092032
[2023-12-16T14:20:32.252+0500] {standard_task_runner.py:104} ERROR - Failed to execute job 50 for task git_push (Bash command failed. The command returned a non-zero exit code 128.; 25450)
[2023-12-16T14:20:32.259+0500] {local_task_job_runner.py:228} INFO - Task exited with return code 1
[2023-12-16T14:20:32.276+0500] {taskinstance.py:2778} INFO - 0 downstream tasks scheduled from follow-on schedule check
