[2023-12-16T13:55:12.595+0500] {taskinstance.py:1159} INFO - Dependencies all met for dep_context=non-requeueable deps ti=<TaskInstance: etl_json_dag.dvc_push manual__2023-12-16T08:54:54.832273+00:00 [queued]>
[2023-12-16T13:55:12.599+0500] {taskinstance.py:1159} INFO - Dependencies all met for dep_context=requeueable deps ti=<TaskInstance: etl_json_dag.dvc_push manual__2023-12-16T08:54:54.832273+00:00 [queued]>
[2023-12-16T13:55:12.600+0500] {taskinstance.py:1361} INFO - Starting attempt 1 of 2
[2023-12-16T13:55:12.618+0500] {taskinstance.py:1382} INFO - Executing <Task(BashOperator): dvc_push> on 2023-12-16 08:54:54.832273+00:00
[2023-12-16T13:55:12.620+0500] {standard_task_runner.py:57} INFO - Started process 18987 to run task
[2023-12-16T13:55:12.624+0500] {standard_task_runner.py:84} INFO - Running: ['airflow', 'tasks', 'run', 'etl_json_dag', 'dvc_push', 'manual__2023-12-16T08:54:54.832273+00:00', '--job-id', '34', '--raw', '--subdir', 'DAGS_FOLDER/etl_dag.py', '--cfg-path', '/tmp/tmpzjz6bf6w']
[2023-12-16T13:55:12.625+0500] {standard_task_runner.py:85} INFO - Job 34: Subtask dvc_push
[2023-12-16T13:55:12.662+0500] {task_command.py:416} INFO - Running <TaskInstance: etl_json_dag.dvc_push manual__2023-12-16T08:54:54.832273+00:00 [running]> on host DESKTOP-32G5QSE.
[2023-12-16T13:55:12.720+0500] {taskinstance.py:1662} INFO - Exporting env vars: AIRFLOW_CTX_DAG_OWNER='airflow' AIRFLOW_CTX_DAG_ID='etl_json_dag' AIRFLOW_CTX_TASK_ID='dvc_push' AIRFLOW_CTX_EXECUTION_DATE='2023-12-16T08:54:54.832273+00:00' AIRFLOW_CTX_TRY_NUMBER='1' AIRFLOW_CTX_DAG_RUN_ID='manual__2023-12-16T08:54:54.832273+00:00'
[2023-12-16T13:55:12.725+0500] {subprocess.py:63} INFO - Tmp dir root location: /tmp
[2023-12-16T13:55:12.725+0500] {subprocess.py:75} INFO - Running command: ['/usr/bin/bash', '-c', 'cd /home/sourav/airflow && dvc push']
[2023-12-16T13:55:12.729+0500] {subprocess.py:86} INFO - Output:
[2023-12-16T13:55:13.175+0500] {subprocess.py:93} INFO - ERROR: failed to push data to the cloud - config file error: no remote specified in /home/sourav/airflow. Create a default remote with
[2023-12-16T13:55:13.176+0500] {subprocess.py:93} INFO -     dvc remote add -d <remote name> <remote url>
[2023-12-16T13:55:13.299+0500] {subprocess.py:97} INFO - Command exited with return code 1
[2023-12-16T13:55:13.305+0500] {taskinstance.py:1937} ERROR - Task failed with exception
Traceback (most recent call last):
  File "/home/sourav/.local/lib/python3.10/site-packages/airflow/operators/bash.py", line 210, in execute
    raise AirflowException(
airflow.exceptions.AirflowException: Bash command failed. The command returned a non-zero exit code 1.
[2023-12-16T13:55:13.308+0500] {taskinstance.py:1400} INFO - Marking task as UP_FOR_RETRY. dag_id=etl_json_dag, task_id=dvc_push, execution_date=20231216T085454, start_date=20231216T085512, end_date=20231216T085513
[2023-12-16T13:55:13.346+0500] {standard_task_runner.py:104} ERROR - Failed to execute job 34 for task dvc_push (Bash command failed. The command returned a non-zero exit code 1.; 18987)
[2023-12-16T13:55:13.359+0500] {local_task_job_runner.py:228} INFO - Task exited with return code 1
[2023-12-16T13:55:13.377+0500] {taskinstance.py:2778} INFO - 0 downstream tasks scheduled from follow-on schedule check
