[2023-12-16T14:23:14.609+0500] {taskinstance.py:1159} INFO - Dependencies all met for dep_context=non-requeueable deps ti=<TaskInstance: etl_json_dag.git_push manual__2023-12-16T09:17:52.279798+00:00 [queued]>
[2023-12-16T14:23:14.614+0500] {taskinstance.py:1159} INFO - Dependencies all met for dep_context=requeueable deps ti=<TaskInstance: etl_json_dag.git_push manual__2023-12-16T09:17:52.279798+00:00 [queued]>
[2023-12-16T14:23:14.614+0500] {taskinstance.py:1361} INFO - Starting attempt 2 of 2
[2023-12-16T14:23:14.635+0500] {taskinstance.py:1382} INFO - Executing <Task(BashOperator): git_push> on 2023-12-16 09:17:52.279798+00:00
[2023-12-16T14:23:14.637+0500] {standard_task_runner.py:57} INFO - Started process 26181 to run task
[2023-12-16T14:23:14.640+0500] {standard_task_runner.py:84} INFO - Running: ['airflow', 'tasks', 'run', 'etl_json_dag', 'git_push', 'manual__2023-12-16T09:17:52.279798+00:00', '--job-id', '51', '--raw', '--subdir', 'DAGS_FOLDER/etl_dag.py', '--cfg-path', '/tmp/tmpzhp_51ub']
[2023-12-16T14:23:14.640+0500] {standard_task_runner.py:85} INFO - Job 51: Subtask git_push
[2023-12-16T14:23:14.679+0500] {task_command.py:416} INFO - Running <TaskInstance: etl_json_dag.git_push manual__2023-12-16T09:17:52.279798+00:00 [running]> on host DESKTOP-32G5QSE.
[2023-12-16T14:23:14.736+0500] {taskinstance.py:1662} INFO - Exporting env vars: AIRFLOW_CTX_DAG_OWNER='airflow' AIRFLOW_CTX_DAG_ID='etl_json_dag' AIRFLOW_CTX_TASK_ID='git_push' AIRFLOW_CTX_EXECUTION_DATE='2023-12-16T09:17:52.279798+00:00' AIRFLOW_CTX_TRY_NUMBER='2' AIRFLOW_CTX_DAG_RUN_ID='manual__2023-12-16T09:17:52.279798+00:00'
[2023-12-16T14:23:14.741+0500] {subprocess.py:63} INFO - Tmp dir root location: /tmp
[2023-12-16T14:23:14.742+0500] {subprocess.py:75} INFO - Running command: ['/usr/bin/bash', '-c', 'cd /home/sourav/airflow && git push']
[2023-12-16T14:23:14.746+0500] {subprocess.py:86} INFO - Output:
[2023-12-16T14:23:15.377+0500] {subprocess.py:93} INFO - fatal: could not read Username for 'https://github.com': No such device or address
[2023-12-16T14:23:15.379+0500] {subprocess.py:97} INFO - Command exited with return code 128
[2023-12-16T14:23:15.384+0500] {taskinstance.py:1937} ERROR - Task failed with exception
Traceback (most recent call last):
  File "/home/sourav/.local/lib/python3.10/site-packages/airflow/operators/bash.py", line 210, in execute
    raise AirflowException(
airflow.exceptions.AirflowException: Bash command failed. The command returned a non-zero exit code 128.
[2023-12-16T14:23:15.387+0500] {taskinstance.py:1400} INFO - Marking task as FAILED. dag_id=etl_json_dag, task_id=git_push, execution_date=20231216T091752, start_date=20231216T092314, end_date=20231216T092315
[2023-12-16T14:23:15.406+0500] {standard_task_runner.py:104} ERROR - Failed to execute job 51 for task git_push (Bash command failed. The command returned a non-zero exit code 128.; 26181)
[2023-12-16T14:23:15.419+0500] {local_task_job_runner.py:228} INFO - Task exited with return code 1
[2023-12-16T14:23:15.429+0500] {taskinstance.py:2778} INFO - 0 downstream tasks scheduled from follow-on schedule check
