[2023-12-16T13:13:09.943+0500] {taskinstance.py:1159} INFO - Dependencies all met for dep_context=non-requeueable deps ti=<TaskInstance: etl_json_dag.transform manual__2023-12-16T08:07:47.564515+00:00 [queued]>
[2023-12-16T13:13:09.949+0500] {taskinstance.py:1159} INFO - Dependencies all met for dep_context=requeueable deps ti=<TaskInstance: etl_json_dag.transform manual__2023-12-16T08:07:47.564515+00:00 [queued]>
[2023-12-16T13:13:09.950+0500] {taskinstance.py:1361} INFO - Starting attempt 2 of 3
[2023-12-16T13:13:09.971+0500] {taskinstance.py:1382} INFO - Executing <Task(PythonOperator): transform> on 2023-12-16 08:07:47.564515+00:00
[2023-12-16T13:13:09.973+0500] {standard_task_runner.py:57} INFO - Started process 9578 to run task
[2023-12-16T13:13:09.977+0500] {standard_task_runner.py:84} INFO - Running: ['airflow', 'tasks', 'run', 'etl_json_dag', 'transform', 'manual__2023-12-16T08:07:47.564515+00:00', '--job-id', '17', '--raw', '--subdir', 'DAGS_FOLDER/etl_dag.py', '--cfg-path', '/tmp/tmpffvdeyyu']
[2023-12-16T13:13:09.977+0500] {standard_task_runner.py:85} INFO - Job 17: Subtask transform
[2023-12-16T13:13:10.031+0500] {task_command.py:416} INFO - Running <TaskInstance: etl_json_dag.transform manual__2023-12-16T08:07:47.564515+00:00 [running]> on host DESKTOP-32G5QSE.
[2023-12-16T13:13:10.110+0500] {taskinstance.py:1662} INFO - Exporting env vars: AIRFLOW_CTX_DAG_OWNER='airflow' AIRFLOW_CTX_DAG_ID='etl_json_dag' AIRFLOW_CTX_TASK_ID='transform' AIRFLOW_CTX_EXECUTION_DATE='2023-12-16T08:07:47.564515+00:00' AIRFLOW_CTX_TRY_NUMBER='2' AIRFLOW_CTX_DAG_RUN_ID='manual__2023-12-16T08:07:47.564515+00:00'
[2023-12-16T13:13:10.111+0500] {etl_dag.py:20} INFO - Data received in transform_data: {'size': 1, 'parse_time_nanoseconds': 20705, 'object_or_array': 'object', 'validate': True, 'empty': False}
[2023-12-16T13:13:10.111+0500] {taskinstance.py:1937} ERROR - Task failed with exception
Traceback (most recent call last):
  File "/home/sourav/.local/lib/python3.10/site-packages/airflow/operators/python.py", line 192, in execute
    return_value = self.execute_callable()
  File "/home/sourav/.local/lib/python3.10/site-packages/airflow/operators/python.py", line 209, in execute_callable
    return self.python_callable(*self.op_args, **self.op_kwargs)
  File "/home/sourav/airflow/dags/etl_dag.py", line 22, in transform_data
    data['new_field'] = 'example_value'
TypeError: 'str' object does not support item assignment
[2023-12-16T13:13:10.115+0500] {taskinstance.py:1400} INFO - Marking task as UP_FOR_RETRY. dag_id=etl_json_dag, task_id=transform, execution_date=20231216T080747, start_date=20231216T081309, end_date=20231216T081310
[2023-12-16T13:13:10.131+0500] {standard_task_runner.py:104} ERROR - Failed to execute job 17 for task transform ('str' object does not support item assignment; 9578)
[2023-12-16T13:13:10.150+0500] {local_task_job_runner.py:228} INFO - Task exited with return code 1
[2023-12-16T13:13:10.170+0500] {taskinstance.py:2778} INFO - 0 downstream tasks scheduled from follow-on schedule check
